<?xml version='1.0'?>
<sdf version='1.7'>
  <model name='tarot_t18'>
    <link name='frame'>
      <inertial>
        <mass>2</mass>
        <inertia>
          <ixx>0.0030625</ixx>
          <ixy>0</ixy>
          <ixz>0</ixz>
          <iyy>0.0030625</iyy>
          <iyz>0</iyz>
          <izz>0.006</izz>
        </inertia>
        <pose>0 0 0.04 0 -0 0</pose>
      </inertial>
      <pose>0 0 0 0 -0 0</pose>
      <gravity>1</gravity>
      <self_collide>0</self_collide>
      <kinematic>0</kinematic>
      <enable_wind>1</enable_wind>
      <visual name='visual'>
        <pose>0 0 0 0 -0 0</pose>
        <geometry>
          <mesh>
            <uri>/home/myerdc18/gymfc/tarot/tarot_t18/meshes/tarot_frame.dae</uri>
            <scale>1 1 1</scale>
          </mesh>
        </geometry>
        <material>
          <lighting>1</lighting>
          <script>
            <uri>file://media/materials/scripts/gazebo.material</uri>
            <name>Gazebo/Black</name>
          </script>
          <shader type='pixel'>
            <normal_map>__default__</normal_map>
          </shader>
          <ambient>0.3 0.3 0.3 1</ambient>
          <diffuse>0.7 0.7 0.7 1</diffuse>
          <specular>0.01 0.01 0.01 1</specular>
          <emissive>0 0 0 1</emissive>
        </material>
        <transparency>0</transparency>
        <cast_shadows>1</cast_shadows>
      </visual>
      <collision name='collision_1'>
        <laser_retro>0</laser_retro>
        <max_contacts>10</max_contacts>
        <pose>0 0 0 0 -0 0</pose>
        <geometry>
          <mesh>
            <uri>/home/myerdc18/gymfc/tarot/tarot_t18/meshes/tarot_frame.dae</uri>
            <scale>1 1 1</scale>
          </mesh>
        </geometry>
        <surface>
          <friction>
            <ode>
              <mu>1</mu>
              <mu2>1</mu2>
              <fdir1>0 0 0</fdir1>
              <slip1>0</slip1>
              <slip2>0</slip2>
            </ode>
            <torsional>
              <coefficient>1</coefficient>
              <patch_radius>0</patch_radius>
              <surface_radius>0</surface_radius>
              <use_patch_radius>1</use_patch_radius>
              <ode>
                <slip>0</slip>
              </ode>
            </torsional>
          </friction>
          <bounce>
            <restitution_coefficient>0</restitution_coefficient>
            <threshold>1e+06</threshold>
          </bounce>
          <contact>
            <collide_without_contact>0</collide_without_contact>
            <collide_without_contact_bitmask>1</collide_without_contact_bitmask>
            <collide_bitmask>1</collide_bitmask>
            <ode>
              <soft_cfm>0</soft_cfm>
              <soft_erp>0.2</soft_erp>
              <kp>1e+13</kp>
              <kd>1</kd>
              <max_vel>0.01</max_vel>
              <min_depth>0</min_depth>
            </ode>
            <bullet>
              <split_impulse>1</split_impulse>
              <split_impulse_penetration_threshold>-0.01</split_impulse_penetration_threshold>
              <soft_cfm>0</soft_cfm>
              <soft_erp>0.2</soft_erp>
              <kp>1e+13</kp>
              <kd>1</kd>
            </bullet>
          </contact>
        </surface>
      </collision>
    </link>
    <link name='battery'>
      <inertial>
        <mass>2.65</mass>
        <inertia>
          <ixx>0.0110704</ixx>
          <ixy>0</ixy>
          <ixz>0</ixz>
          <iyy>0.00308659</iyy>
          <iyz>0</iyz>
          <izz>0.0120542</izz>
        </inertia>
        <pose>0 0 0 0 -0 0</pose>
      </inertial>
      <pose>0 0 -0.05 0 -0 0</pose>
      <self_collide>0</self_collide>
      <enable_wind>1</enable_wind>
      <kinematic>0</kinematic>
      <gravity>1</gravity>
      <visual name='visual'>
        <pose>0 0 0 0 -0 0</pose>
        <geometry>
          <box>
            <size>0.096 0.213 0.069</size>
          </box>
        </geometry>
        <material>
          <lighting>1</lighting>
          <script>
            <uri>file://media/materials/scripts/gazebo.material</uri>
            <name>Gazebo/Yellow</name>
          </script>
          <shader type='pixel'>
            <normal_map>__default__</normal_map>
          </shader>
          <emissive>0 0 0 1</emissive>
          <ambient>1 1 0 1</ambient>
          <diffuse>1 1 0 1</diffuse>
        </material>
        <transparency>0</transparency>
        <cast_shadows>1</cast_shadows>
      </visual>
    </link>
    <link name='motor_1'>
      <inertial>
        <mass>0.175</mass>
        <inertia>
          <ixx>4.227e-05</ixx>
          <ixy>0</ixy>
          <ixz>0</ixz>
          <iyy>4.227e-05</iyy>
          <iyz>0</iyz>
          <izz>5.082e-05</izz>
        </inertia>
        <pose>0 0 0 0 -0 0</pose>
      </inertial>
      <pose>0 0.635 0 0 -0 0</pose>
      <gravity>1</gravity>
      <self_collide>0</self_collide>
      <kinematic>0</kinematic>
      <enable_wind>1</enable_wind>
      <visual name='visual'>
        <pose>0 0 0.01 0 -0 0</pose>
        <geometry>
          <cylinder>
            <radius>0.0241</radius>
            <length>0.034</length>
          </cylinder>
        </geometry>
        <material>
          <lighting>1</lighting>
          <script>
            <uri>file://media/materials/scripts/gazebo.material</uri>
            <name>Gazebo/White</name>
          </script>
          <shader type='pixel'>
            <normal_map>__default__</normal_map>
          </shader>
          <ambient>0.3 0.3 0.3 1</ambient>
          <diffuse>0.7 0.7 0.7 1</diffuse>
          <specular>0.01 0.01 0.01 1</specular>
          <emissive>0 0 0 1</emissive>
        </material>
        <transparency>0</transparency>
        <cast_shadows>1</cast_shadows>
      </visual>
    </link>
    <link name='motor_2'>
      <inertial>
        <mass>0.175</mass>
        <inertia>
          <ixx>4.227e-05</ixx>
          <ixy>0</ixy>
          <ixz>0</ixz>
          <iyy>4.227e-05</iyy>
          <iyz>0</iyz>
          <izz>5.082e-05</izz>
        </inertia>
        <pose>0 0 0 0 -0 0</pose>
      </inertial>
      <pose>0.449013 0.449013 0 0 -0 0</pose>
      <gravity>1</gravity>
      <self_collide>0</self_collide>
      <kinematic>0</kinematic>
      <enable_wind>1</enable_wind>
      <visual name='visual'>
        <pose>0 0 0.01 0 -0 0</pose>
        <geometry>
          <cylinder>
            <radius>0.0241</radius>
            <length>0.034</length>
          </cylinder>
        </geometry>
        <material>
          <lighting>1</lighting>
          <script>
            <uri>file://media/materials/scripts/gazebo.material</uri>
            <name>Gazebo/White</name>
          </script>
          <shader type='pixel'>
            <normal_map>__default__</normal_map>
          </shader>
          <ambient>0.3 0.3 0.3 1</ambient>
          <diffuse>0.7 0.7 0.7 1</diffuse>
          <specular>0.01 0.01 0.01 1</specular>
          <emissive>0 0 0 1</emissive>
        </material>
        <transparency>0</transparency>
        <cast_shadows>1</cast_shadows>
      </visual>
    </link>
    <link name='motor_3'>
      <inertial>
        <mass>0.175</mass>
        <inertia>
          <ixx>4.227e-05</ixx>
          <ixy>0</ixy>
          <ixz>0</ixz>
          <iyy>4.227e-05</iyy>
          <iyz>0</iyz>
          <izz>5.082e-05</izz>
        </inertia>
        <pose>0 0 0 0 -0 0</pose>
      </inertial>
      <pose>0.635 0 0 0 -0 0</pose>
      <gravity>1</gravity>
      <self_collide>0</self_collide>
      <kinematic>0</kinematic>
      <enable_wind>1</enable_wind>
      <visual name='visual'>
        <pose>0 0 0.01 0 -0 0</pose>
        <geometry>
          <cylinder>
            <radius>0.0241</radius>
            <length>0.034</length>
          </cylinder>
        </geometry>
        <material>
          <lighting>1</lighting>
          <script>
            <uri>file://media/materials/scripts/gazebo.material</uri>
            <name>Gazebo/White</name>
          </script>
          <shader type='pixel'>
            <normal_map>__default__</normal_map>
          </shader>
          <ambient>0.3 0.3 0.3 1</ambient>
          <diffuse>0.7 0.7 0.7 1</diffuse>
          <specular>0.01 0.01 0.01 1</specular>
          <emissive>0 0 0 1</emissive>
        </material>
        <transparency>0</transparency>
        <cast_shadows>1</cast_shadows>
      </visual>
    </link>
    <link name='motor_4'>
      <inertial>
        <mass>0.175</mass>
        <inertia>
          <ixx>4.227e-05</ixx>
          <ixy>0</ixy>
          <ixz>0</ixz>
          <iyy>4.227e-05</iyy>
          <iyz>0</iyz>
          <izz>5.082e-05</izz>
        </inertia>
        <pose>0 0 0 0 -0 0</pose>
      </inertial>
      <pose>0.449013 -0.449013 0 0 -0 0</pose>
      <gravity>1</gravity>
      <self_collide>0</self_collide>
      <kinematic>0</kinematic>
      <enable_wind>1</enable_wind>
      <visual name='visual'>
        <pose>0 0 0.01 0 -0 0</pose>
        <geometry>
          <cylinder>
            <radius>0.0241</radius>
            <length>0.034</length>
          </cylinder>
        </geometry>
        <material>
          <lighting>1</lighting>
          <script>
            <uri>file://media/materials/scripts/gazebo.material</uri>
            <name>Gazebo/White</name>
          </script>
          <shader type='pixel'>
            <normal_map>__default__</normal_map>
          </shader>
          <ambient>0.3 0.3 0.3 1</ambient>
          <diffuse>0.7 0.7 0.7 1</diffuse>
          <specular>0.01 0.01 0.01 1</specular>
          <emissive>0 0 0 1</emissive>
        </material>
        <transparency>0</transparency>
        <cast_shadows>1</cast_shadows>
      </visual>
    </link>
    <link name='motor_5'>
      <inertial>
        <mass>0.175</mass>
        <inertia>
          <ixx>4.227e-05</ixx>
          <ixy>0</ixy>
          <ixz>0</ixz>
          <iyy>4.227e-05</iyy>
          <iyz>0</iyz>
          <izz>5.082e-05</izz>
        </inertia>
        <pose>0 0 0 0 -0 0</pose>
      </inertial>
      <pose>0 -0.635 0 0 -0 0</pose>
      <gravity>1</gravity>
      <self_collide>0</self_collide>
      <kinematic>0</kinematic>
      <enable_wind>1</enable_wind>
      <visual name='visual'>
        <pose>0 0 0.01 0 -0 0</pose>
        <geometry>
          <cylinder>
            <radius>0.0241</radius>
            <length>0.034</length>
          </cylinder>
        </geometry>
        <material>
          <lighting>1</lighting>
          <script>
            <uri>file://media/materials/scripts/gazebo.material</uri>
            <name>Gazebo/White</name>
          </script>
          <shader type='pixel'>
            <normal_map>__default__</normal_map>
          </shader>
          <ambient>0.3 0.3 0.3 1</ambient>
          <diffuse>0.7 0.7 0.7 1</diffuse>
          <specular>0.01 0.01 0.01 1</specular>
          <emissive>0 0 0 1</emissive>
        </material>
        <transparency>0</transparency>
        <cast_shadows>1</cast_shadows>
      </visual>
    </link>
    <link name='motor_6'>
      <inertial>
        <mass>0.175</mass>
        <inertia>
          <ixx>4.227e-05</ixx>
          <ixy>0</ixy>
          <ixz>0</ixz>
          <iyy>4.227e-05</iyy>
          <iyz>0</iyz>
          <izz>5.082e-05</izz>
        </inertia>
        <pose>0 0 0 0 -0 0</pose>
      </inertial>
      <pose>-0.449013 -0.449013 0 0 -0 0</pose>
      <gravity>1</gravity>
      <self_collide>0</self_collide>
      <kinematic>0</kinematic>
      <enable_wind>1</enable_wind>
      <visual name='visual'>
        <pose>0 0 0.01 0 -0 0</pose>
        <geometry>
          <cylinder>
            <radius>0.0241</radius>
            <length>0.034</length>
          </cylinder>
        </geometry>
        <material>
          <lighting>1</lighting>
          <script>
            <uri>file://media/materials/scripts/gazebo.material</uri>
            <name>Gazebo/White</name>
          </script>
          <shader type='pixel'>
            <normal_map>__default__</normal_map>
          </shader>
          <ambient>0.3 0.3 0.3 1</ambient>
          <diffuse>0.7 0.7 0.7 1</diffuse>
          <specular>0.01 0.01 0.01 1</specular>
          <emissive>0 0 0 1</emissive>
        </material>
        <transparency>0</transparency>
        <cast_shadows>1</cast_shadows>
      </visual>
    </link>
    <link name='motor_7'>
      <inertial>
        <mass>0.175</mass>
        <inertia>
          <ixx>4.227e-05</ixx>
          <ixy>0</ixy>
          <ixz>0</ixz>
          <iyy>4.227e-05</iyy>
          <iyz>0</iyz>
          <izz>5.082e-05</izz>
        </inertia>
        <pose>0 0 0 0 -0 0</pose>
      </inertial>
      <pose>-0.635 0 0 0 -0 0</pose>
      <gravity>1</gravity>
      <self_collide>0</self_collide>
      <kinematic>0</kinematic>
      <enable_wind>1</enable_wind>
      <visual name='visual'>
        <pose>0 0 0.01 0 -0 0</pose>
        <geometry>
          <cylinder>
            <radius>0.0241</radius>
            <length>0.034</length>
          </cylinder>
        </geometry>
        <material>
          <lighting>1</lighting>
          <script>
            <uri>file://media/materials/scripts/gazebo.material</uri>
            <name>Gazebo/White</name>
          </script>
          <shader type='pixel'>
            <normal_map>__default__</normal_map>
          </shader>
          <ambient>0.3 0.3 0.3 1</ambient>
          <diffuse>0.7 0.7 0.7 1</diffuse>
          <specular>0.01 0.01 0.01 1</specular>
          <emissive>0 0 0 1</emissive>
        </material>
        <transparency>0</transparency>
        <cast_shadows>1</cast_shadows>
      </visual>
    </link>
    <link name='motor_8'>
      <inertial>
        <mass>0.175</mass>
        <inertia>
          <ixx>4.227e-05</ixx>
          <ixy>0</ixy>
          <ixz>0</ixz>
          <iyy>4.227e-05</iyy>
          <iyz>0</iyz>
          <izz>5.082e-05</izz>
        </inertia>
        <pose>0 0 0 0 -0 0</pose>
      </inertial>
      <pose>-0.449013 0.449013 0 0 -0 0</pose>
      <gravity>1</gravity>
      <self_collide>0</self_collide>
      <kinematic>0</kinematic>
      <enable_wind>1</enable_wind>
      <visual name='visual'>
        <pose>0 0 0.01 0 -0 0</pose>
        <geometry>
          <cylinder>
            <radius>0.0241</radius>
            <length>0.034</length>
          </cylinder>
        </geometry>
        <material>
          <lighting>1</lighting>
          <script>
            <uri>file://media/materials/scripts/gazebo.material</uri>
            <name>Gazebo/White</name>
          </script>
          <shader type='pixel'>
            <normal_map>__default__</normal_map>
          </shader>
          <ambient>0.3 0.3 0.3 1</ambient>
          <diffuse>0.7 0.7 0.7 1</diffuse>
          <specular>0.01 0.01 0.01 1</specular>
          <emissive>0 0 0 1</emissive>
        </material>
        <transparency>0</transparency>
        <cast_shadows>1</cast_shadows>
      </visual>
    </link>
    <link name='prop_1'>
      <inertial>
        <mass>1</mass>
        <inertia>
          <ixx>0.166667</ixx>
          <ixy>0</ixy>
          <ixz>0</ixz>
          <iyy>0.166667</iyy>
          <iyz>0</iyz>
          <izz>0.166667</izz>
        </inertia>
        <pose>0 0 0 0 -0 0</pose>
      </inertial>
      <pose>0 0.635 0.035 0 -0 0</pose>
      <gravity>1</gravity>
      <self_collide>0</self_collide>
      <kinematic>0</kinematic>
      <enable_wind>0</enable_wind>
      <visual name='visual'>
        <pose>0.01 0 0 0 -0 0</pose>
        <geometry>
          <mesh>
            <uri>/home/myerdc18/gymfc/tarot/tarot_t18/meshes/CCW_edited.dae</uri>
          </mesh>
        </geometry>
        <material>
          <lighting>1</lighting>
          <script>
            <uri>file://media/materials/scripts/gazebo.material</uri>
            <name>Gazebo/Grey</name>
          </script>
          <shader type='pixel'>
            <normal_map>__default__</normal_map>
          </shader>
          <ambient>0.3 0.3 0.3 1</ambient>
          <diffuse>0.7 0.7 0.7 1</diffuse>
          <specular>0.01 0.01 0.01 1</specular>
          <emissive>0 0 0 1</emissive>
        </material>
        <transparency>0</transparency>
        <cast_shadows>1</cast_shadows>
      </visual>
    </link>
    <link name='prop_2'>
      <inertial>
        <mass>1</mass>
        <inertia>
          <ixx>0.166667</ixx>
          <ixy>0</ixy>
          <ixz>0</ixz>
          <iyy>0.166667</iyy>
          <iyz>0</iyz>
          <izz>0.166667</izz>
        </inertia>
        <pose>0 0 0 0 -0 0</pose>
      </inertial>
      <pose>0.449013 0.449013 0.035 0 -0 0</pose>
      <gravity>1</gravity>
      <self_collide>0</self_collide>
      <kinematic>0</kinematic>
      <enable_wind>0</enable_wind>
      <visual name='visual'>
        <pose>-0.02 0 0 0 -0 0</pose>
        <geometry>
          <mesh>
            <uri>/home/myerdc18/gymfc/tarot/tarot_t18/meshes/CW_edited.dae</uri>
          </mesh>
        </geometry>
        <material>
          <lighting>1</lighting>
          <script>
            <uri>file://media/materials/scripts/gazebo.material</uri>
            <name>Gazebo/Grey</name>
          </script>
          <shader type='pixel'>
            <normal_map>__default__</normal_map>
          </shader>
          <ambient>0.3 0.3 0.3 1</ambient>
          <diffuse>0.7 0.7 0.7 1</diffuse>
          <specular>0.01 0.01 0.01 1</specular>
          <emissive>0 0 0 1</emissive>
        </material>
        <transparency>0</transparency>
        <cast_shadows>1</cast_shadows>
      </visual>
    </link>
    <link name='prop_3'>
      <inertial>
        <mass>1</mass>
        <inertia>
          <ixx>0.166667</ixx>
          <ixy>0</ixy>
          <ixz>0</ixz>
          <iyy>0.166667</iyy>
          <iyz>0</iyz>
          <izz>0.166667</izz>
        </inertia>
        <pose>0 0 0 0 -0 0</pose>
      </inertial>
      <pose>0.635 0 0.035 0 -0 0</pose>
      <gravity>1</gravity>
      <self_collide>0</self_collide>
      <kinematic>0</kinematic>
      <enable_wind>0</enable_wind>
      <visual name='visual'>
        <pose>0.01 0 0 0 -0 0</pose>
        <geometry>
          <mesh>
            <uri>/home/myerdc18/gymfc/tarot/tarot_t18/meshes/CCW_edited.dae</uri>
          </mesh>
        </geometry>
        <material>
          <lighting>1</lighting>
          <script>
            <uri>file://media/materials/scripts/gazebo.material</uri>
            <name>Gazebo/Grey</name>
          </script>
          <shader type='pixel'>
            <normal_map>__default__</normal_map>
          </shader>
          <ambient>0.3 0.3 0.3 1</ambient>
          <diffuse>0.7 0.7 0.7 1</diffuse>
          <specular>0.01 0.01 0.01 1</specular>
          <emissive>0 0 0 1</emissive>
        </material>
        <transparency>0</transparency>
        <cast_shadows>1</cast_shadows>
      </visual>
    </link>
    <link name='prop_4'>
      <inertial>
        <mass>1</mass>
        <inertia>
          <ixx>0.166667</ixx>
          <ixy>0</ixy>
          <ixz>0</ixz>
          <iyy>0.166667</iyy>
          <iyz>0</iyz>
          <izz>0.166667</izz>
        </inertia>
        <pose>0 0 0 0 -0 0</pose>
      </inertial>
      <pose>0.449013 -0.449013 0.035 0 -0 0</pose>
      <gravity>1</gravity>
      <self_collide>0</self_collide>
      <kinematic>0</kinematic>
      <enable_wind>0</enable_wind>
      <visual name='visual'>
        <pose>-0.02 0 0 0 -0 0</pose>
        <geometry>
          <mesh>
            <uri>/home/myerdc18/gymfc/tarot/tarot_t18/meshes/CW_edited.dae</uri>
          </mesh>
        </geometry>
        <material>
          <lighting>1</lighting>
          <script>
            <uri>file://media/materials/scripts/gazebo.material</uri>
            <name>Gazebo/Grey</name>
          </script>
          <shader type='pixel'>
            <normal_map>__default__</normal_map>
          </shader>
          <ambient>0.3 0.3 0.3 1</ambient>
          <diffuse>0.7 0.7 0.7 1</diffuse>
          <specular>0.01 0.01 0.01 1</specular>
          <emissive>0 0 0 1</emissive>
        </material>
        <transparency>0</transparency>
        <cast_shadows>1</cast_shadows>
      </visual>
    </link>
    <link name='prop_5'>
      <inertial>
        <mass>1</mass>
        <inertia>
          <ixx>0.166667</ixx>
          <ixy>0</ixy>
          <ixz>0</ixz>
          <iyy>0.166667</iyy>
          <iyz>0</iyz>
          <izz>0.166667</izz>
        </inertia>
        <pose>0 0 0 0 -0 0</pose>
      </inertial>
      <pose>0 -0.635 0.035 0 -0 0</pose>
      <gravity>1</gravity>
      <self_collide>0</self_collide>
      <kinematic>0</kinematic>
      <enable_wind>0</enable_wind>
      <visual name='visual'>
        <pose>0.01 0 0 0 -0 0</pose>
        <geometry>
          <mesh>
            <uri>/home/myerdc18/gymfc/tarot/tarot_t18/meshes/CCW_edited.dae</uri>
          </mesh>
        </geometry>
        <material>
          <lighting>1</lighting>
          <script>
            <uri>file://media/materials/scripts/gazebo.material</uri>
            <name>Gazebo/Grey</name>
          </script>
          <shader type='pixel'>
            <normal_map>__default__</normal_map>
          </shader>
          <ambient>0.3 0.3 0.3 1</ambient>
          <diffuse>0.7 0.7 0.7 1</diffuse>
          <specular>0.01 0.01 0.01 1</specular>
          <emissive>0 0 0 1</emissive>
        </material>
        <transparency>0</transparency>
        <cast_shadows>1</cast_shadows>
      </visual>
    </link>
    <link name='prop_6'>
      <inertial>
        <mass>1</mass>
        <inertia>
          <ixx>0.166667</ixx>
          <ixy>0</ixy>
          <ixz>0</ixz>
          <iyy>0.166667</iyy>
          <iyz>0</iyz>
          <izz>0.166667</izz>
        </inertia>
        <pose>0 0 0 0 -0 0</pose>
      </inertial>
      <pose>-0.449013 -0.449013 0.035 0 -0 0</pose>
      <gravity>1</gravity>
      <self_collide>0</self_collide>
      <kinematic>0</kinematic>
      <enable_wind>0</enable_wind>
      <visual name='visual'>
        <pose>-0.02 0 0 0 -0 0</pose>
        <geometry>
          <mesh>
            <uri>/home/myerdc18/gymfc/tarot/tarot_t18/meshes/CW_edited.dae</uri>
          </mesh>
        </geometry>
        <material>
          <lighting>1</lighting>
          <script>
            <uri>file://media/materials/scripts/gazebo.material</uri>
            <name>Gazebo/Grey</name>
          </script>
          <shader type='pixel'>
            <normal_map>__default__</normal_map>
          </shader>
          <ambient>0.3 0.3 0.3 1</ambient>
          <diffuse>0.7 0.7 0.7 1</diffuse>
          <specular>0.01 0.01 0.01 1</specular>
          <emissive>0 0 0 1</emissive>
        </material>
        <transparency>0</transparency>
        <cast_shadows>1</cast_shadows>
      </visual>
    </link>
    <link name='prop_7'>
      <inertial>
        <mass>1</mass>
        <inertia>
          <ixx>0.166667</ixx>
          <ixy>0</ixy>
          <ixz>0</ixz>
          <iyy>0.166667</iyy>
          <iyz>0</iyz>
          <izz>0.166667</izz>
        </inertia>
        <pose>0 0 0 0 -0 0</pose>
      </inertial>
      <pose>-0.635 0 0.035 0 -0 0</pose>
      <gravity>1</gravity>
      <self_collide>0</self_collide>
      <kinematic>0</kinematic>
      <enable_wind>0</enable_wind>
      <visual name='visual'>
        <pose>0.01 0 0 0 -0 0</pose>
        <geometry>
          <mesh>
            <uri>/home/myerdc18/gymfc/tarot/tarot_t18/meshes/CCW_edited.dae</uri>
          </mesh>
        </geometry>
        <material>
          <lighting>1</lighting>
          <script>
            <uri>file://media/materials/scripts/gazebo.material</uri>
            <name>Gazebo/Grey</name>
          </script>
          <shader type='pixel'>
            <normal_map>__default__</normal_map>
          </shader>
          <ambient>0.3 0.3 0.3 1</ambient>
          <diffuse>0.7 0.7 0.7 1</diffuse>
          <specular>0.01 0.01 0.01 1</specular>
          <emissive>0 0 0 1</emissive>
        </material>
        <transparency>0</transparency>
        <cast_shadows>1</cast_shadows>
      </visual>
    </link>
    <link name='prop_8'>
      <inertial>
        <mass>1</mass>
        <inertia>
          <ixx>0.166667</ixx>
          <ixy>0</ixy>
          <ixz>0</ixz>
          <iyy>0.166667</iyy>
          <iyz>0</iyz>
          <izz>0.166667</izz>
        </inertia>
        <pose>0 0 0 0 -0 0</pose>
      </inertial>
      <pose>-0.449013 0.449013 0.035 0 -0 0</pose>
      <gravity>1</gravity>
      <self_collide>0</self_collide>
      <kinematic>0</kinematic>
      <enable_wind>0</enable_wind>
      <visual name='visual'>
        <pose>-0.02 0 0 0 -0 0</pose>
        <geometry>
          <mesh>
            <uri>/home/myerdc18/gymfc/tarot/tarot_t18/meshes/CW_edited.dae</uri>
          </mesh>
        </geometry>
        <material>
          <lighting>1</lighting>
          <script>
            <uri>file://media/materials/scripts/gazebo.material</uri>
            <name>Gazebo/Grey</name>
          </script>
          <shader type='pixel'>
            <normal_map>__default__</normal_map>
          </shader>
          <ambient>0.3 0.3 0.3 1</ambient>
          <diffuse>0.7 0.7 0.7 1</diffuse>
          <specular>0.01 0.01 0.01 1</specular>
          <emissive>0 0 0 1</emissive>
        </material>
        <transparency>0</transparency>
        <cast_shadows>1</cast_shadows>
      </visual>
    </link>
    <joint name='battery_joint' type='fixed'>
      <parent>frame</parent>
      <child>battery</child>
      <pose>0 0 0 0 -0 0</pose>
      <physics>
        <ode>
          <limit>
            <cfm>0</cfm>
            <erp>0.2</erp>
          </limit>
          <suspension>
            <cfm>0</cfm>
            <erp>0.2</erp>
          </suspension>
        </ode>
      </physics>
    </joint>
    <joint name='motor_1_joint' type='fixed'>
      <parent>frame</parent>
      <child>motor_1</child>
      <pose>0 0 0 0 -0 0</pose>
      <physics>
        <ode>
          <limit>
            <cfm>0</cfm>
            <erp>0.2</erp>
          </limit>
          <suspension>
            <cfm>0</cfm>
            <erp>0.2</erp>
          </suspension>
        </ode>
      </physics>
    </joint>
    <joint name='motor_2_joint' type='fixed'>
      <parent>frame</parent>
      <child>motor_2</child>
      <pose>0 0 0 0 -0 0</pose>
      <physics>
        <ode>
          <limit>
            <cfm>0</cfm>
            <erp>0.2</erp>
          </limit>
          <suspension>
            <cfm>0</cfm>
            <erp>0.2</erp>
          </suspension>
        </ode>
      </physics>
    </joint>
    <joint name='motor_3_joint' type='fixed'>
      <parent>frame</parent>
      <child>motor_3</child>
      <pose>0 0 0 0 -0 0</pose>
      <physics>
        <ode>
          <limit>
            <cfm>0</cfm>
            <erp>0.2</erp>
          </limit>
          <suspension>
            <cfm>0</cfm>
            <erp>0.2</erp>
          </suspension>
        </ode>
      </physics>
    </joint>
    <joint name='motor_4_joint' type='fixed'>
      <parent>frame</parent>
      <child>motor_4</child>
      <pose>0 0 0 0 -0 0</pose>
      <physics>
        <ode>
          <limit>
            <cfm>0</cfm>
            <erp>0.2</erp>
          </limit>
          <suspension>
            <cfm>0</cfm>
            <erp>0.2</erp>
          </suspension>
        </ode>
      </physics>
    </joint>
    <joint name='motor_5_joint' type='fixed'>
      <parent>frame</parent>
      <child>motor_5</child>
      <pose>0 0 0 0 -0 0</pose>
      <physics>
        <ode>
          <limit>
            <cfm>0</cfm>
            <erp>0.2</erp>
          </limit>
          <suspension>
            <cfm>0</cfm>
            <erp>0.2</erp>
          </suspension>
        </ode>
      </physics>
    </joint>
    <joint name='motor_6_joint' type='fixed'>
      <parent>frame</parent>
      <child>motor_6</child>
      <pose>0 0 0 0 -0 0</pose>
      <physics>
        <ode>
          <limit>
            <cfm>0</cfm>
            <erp>0.2</erp>
          </limit>
          <suspension>
            <cfm>0</cfm>
            <erp>0.2</erp>
          </suspension>
        </ode>
      </physics>
    </joint>
    <joint name='motor_7_joint' type='fixed'>
      <parent>frame</parent>
      <child>motor_7</child>
      <pose>0 0 0 0 -0 0</pose>
      <physics>
        <ode>
          <limit>
            <cfm>0</cfm>
            <erp>0.2</erp>
          </limit>
          <suspension>
            <cfm>0</cfm>
            <erp>0.2</erp>
          </suspension>
        </ode>
      </physics>
    </joint>
    <joint name='motor_8_joint' type='fixed'>
      <parent>frame</parent>
      <child>motor_8</child>
      <pose>0 0 0 0 -0 0</pose>
      <physics>
        <ode>
          <limit>
            <cfm>0</cfm>
            <erp>0.2</erp>
          </limit>
          <suspension>
            <cfm>0</cfm>
            <erp>0.2</erp>
          </suspension>
        </ode>
      </physics>
    </joint>
    <joint name='prop_1_joint' type='revolute'>
      <parent>frame</parent>
      <child>prop_1</child>
      <axis>
        <xyz>0 0 1</xyz>
        <limit>
          <lower>-1e+16</lower>
          <upper>1e+16</upper>
        </limit>
        <dynamics>
          <spring_reference>0</spring_reference>
          <spring_stiffness>0</spring_stiffness>
        </dynamics>
        <use_parent_model_frame>1</use_parent_model_frame>
      </axis>
    </joint>
    <joint name='prop_2_joint' type='revolute'>
      <parent>frame</parent>
      <child>prop_2</child>
      <pose>0 0 0 0 -0 0</pose>
      <axis>
        <xyz expressed_in='__model__'>0 0 1</xyz>
        <limit>
          <lower>-1e+16</lower>
          <upper>1e+16</upper>
          <effort>-1</effort>
          <velocity>-1</velocity>
        </limit>
        <dynamics>
          <spring_reference>0</spring_reference>
          <spring_stiffness>0</spring_stiffness>
          <damping>0</damping>
          <friction>0</friction>
        </dynamics>
      </axis>
      <physics>
        <ode>
          <limit>
            <cfm>0</cfm>
            <erp>0.2</erp>
          </limit>
          <suspension>
            <cfm>0</cfm>
            <erp>0.2</erp>
          </suspension>
        </ode>
      </physics>
    </joint>
    <joint name='prop_3_joint' type='revolute'>
      <parent>frame</parent>
      <child>prop_3</child>
      <pose>0 0 0 0 -0 0</pose>
      <axis>
        <xyz expressed_in='__model__'>0 0 1</xyz>
        <limit>
          <lower>-1e+16</lower>
          <upper>1e+16</upper>
          <effort>-1</effort>
          <velocity>-1</velocity>
        </limit>
        <dynamics>
          <spring_reference>0</spring_reference>
          <spring_stiffness>0</spring_stiffness>
          <damping>0</damping>
          <friction>0</friction>
        </dynamics>
      </axis>
      <physics>
        <ode>
          <limit>
            <cfm>0</cfm>
            <erp>0.2</erp>
          </limit>
          <suspension>
            <cfm>0</cfm>
            <erp>0.2</erp>
          </suspension>
        </ode>
      </physics>
    </joint>
    <joint name='prop_4_joint' type='revolute'>
      <parent>frame</parent>
      <child>prop_4</child>
      <pose>0 0 0 0 -0 0</pose>
      <axis>
        <xyz expressed_in='__model__'>0 0 1</xyz>
        <limit>
          <lower>-1e+16</lower>
          <upper>1e+16</upper>
          <effort>-1</effort>
          <velocity>-1</velocity>
        </limit>
        <dynamics>
          <spring_reference>0</spring_reference>
          <spring_stiffness>0</spring_stiffness>
          <damping>0</damping>
          <friction>0</friction>
        </dynamics>
      </axis>
      <physics>
        <ode>
          <limit>
            <cfm>0</cfm>
            <erp>0.2</erp>
          </limit>
          <suspension>
            <cfm>0</cfm>
            <erp>0.2</erp>
          </suspension>
        </ode>
      </physics>
    </joint>
    <joint name='prop_5_joint' type='revolute'>
      <parent>frame</parent>
      <child>prop_5</child>
      <pose>0 0 0 0 -0 0</pose>
      <axis>
        <xyz expressed_in='__model__'>0 0 1</xyz>
        <limit>
          <lower>-1e+16</lower>
          <upper>1e+16</upper>
          <effort>-1</effort>
          <velocity>-1</velocity>
        </limit>
        <dynamics>
          <spring_reference>0</spring_reference>
          <spring_stiffness>0</spring_stiffness>
          <damping>0</damping>
          <friction>0</friction>
        </dynamics>
      </axis>
      <physics>
        <ode>
          <limit>
            <cfm>0</cfm>
            <erp>0.2</erp>
          </limit>
          <suspension>
            <cfm>0</cfm>
            <erp>0.2</erp>
          </suspension>
        </ode>
      </physics>
    </joint>
    <joint name='prop_6_joint' type='revolute'>
      <parent>frame</parent>
      <child>prop_6</child>
      <pose>0 0 0 0 -0 0</pose>
      <axis>
        <xyz expressed_in='__model__'>0 0 1</xyz>
        <limit>
          <lower>-1e+16</lower>
          <upper>1e+16</upper>
          <effort>-1</effort>
          <velocity>-1</velocity>
        </limit>
        <dynamics>
          <spring_reference>0</spring_reference>
          <spring_stiffness>0</spring_stiffness>
          <damping>0</damping>
          <friction>0</friction>
        </dynamics>
      </axis>
      <physics>
        <ode>
          <limit>
            <cfm>0</cfm>
            <erp>0.2</erp>
          </limit>
          <suspension>
            <cfm>0</cfm>
            <erp>0.2</erp>
          </suspension>
        </ode>
      </physics>
    </joint>
    <joint name='prop_7_joint' type='revolute'>
      <parent>frame</parent>
      <child>prop_7</child>
      <pose>0 0 0 0 -0 0</pose>
      <axis>
        <xyz expressed_in='__model__'>1 0 0</xyz>
        <limit>
          <lower>-1e+16</lower>
          <upper>1e+16</upper>
          <effort>-1</effort>
          <velocity>-1</velocity>
        </limit>
        <dynamics>
          <spring_reference>0</spring_reference>
          <spring_stiffness>0</spring_stiffness>
          <damping>0</damping>
          <friction>0</friction>
        </dynamics>
      </axis>
      <physics>
        <ode>
          <limit>
            <cfm>0</cfm>
            <erp>0.2</erp>
          </limit>
          <suspension>
            <cfm>0</cfm>
            <erp>0.2</erp>
          </suspension>
        </ode>
      </physics>
    </joint>
    <joint name='prop_8_joint' type='revolute'>
      <parent>frame</parent>
      <child>prop_8</child>
      <pose>0 0 0 0 -0 0</pose>
      <axis>
        <xyz expressed_in='__model__'>0 0 1</xyz>
        <limit>
          <lower>-1e+16</lower>
          <upper>1e+16</upper>
          <effort>-1</effort>
          <velocity>-1</velocity>
        </limit>
        <dynamics>
          <spring_reference>0</spring_reference>
          <spring_stiffness>0</spring_stiffness>
          <damping>0</damping>
          <friction>0</friction>
        </dynamics>
      </axis>
      <physics>
        <ode>
          <limit>
            <cfm>0</cfm>
            <erp>0.2</erp>
          </limit>
          <suspension>
            <cfm>0</cfm>
            <erp>0.2</erp>
          </suspension>
        </ode>
      </physics>
    </joint>
    <static>0</static>
    <allow_auto_disable>1</allow_auto_disable>
    <plugin name='config' filename='libAircraftConfigPlugin.so'>
      <motorCount>8</motorCount>
      <centerOfThrust>
        <link>battery</link>
        <offset>0 0 0.058</offset>
      </centerOfThrust>
      <sensors>
        <sensor type='imu'>
          <enable_angular_velocity>1</enable_angular_velocity>
          <enable_linear_acceleration>1</enable_linear_acceleration>
          <enable_orientation>1</enable_orientation>
        </sensor>
        <sensor type='esc'>
          <enable_angular_velocity>1</enable_angular_velocity>
          <enable_temperature>0</enable_temperature>
          <enable_current>0</enable_current>
        </sensor>
      </sensors>
    </plugin>
    <plugin name='prop_1_motor_model' filename='libgazebo_motor_model.so'>
      <robotNamespace/>
      <jointName>prop_1_joint</jointName>
      <linkName>prop_1</linkName>
      <turningDirection>ccw</turningDirection>
      <timeConstantUp>0.187</timeConstantUp>
      <timeConstantDown>0.1</timeConstantDown>
      <maxRotVelocity>2622</maxRotVelocity>
      <motorConstant>9.375e-7</motorConstant>
      <momentConstant>0.0086</momentConstant>
      <motorNumber>0</motorNumber>
      <rotorDragCoefficient>8e-5</rotorDragCoefficient>
      <rollingMomentCoefficient>1e-06</rollingMomentCoefficient>
      <rotorVelocitySlowdownSim>1</rotorVelocitySlowdownSim>
      <rotorVelocityUnits>rpm</rotorVelocityUnits>
      <escTransferFunction>
        <term1Coefficient>-14229.32</term1Coefficient>
        <term2Coefficient>39125.59</term2Coefficient>
        <term3Coefficient>86.67</term3Coefficient>
      </escTransferFunction>
      <joint_control_pid>
        <p>0.0001</p>
        <i>0</i>
        <d>0</d>
        <iMin>0</iMin>
        <iMax>0</iMax>
        <cmdMin>-0.05</cmdMin>
        <cmdMax>0.1</cmdMax>
      </joint_control_pid>
    </plugin>
    <plugin name='prop_2_motor_model' filename='libgazebo_motor_model.so'>
      <robotNamespace/>
      <jointName>prop_2_joint</jointName>
      <linkName>prop_2</linkName>
      <turningDirection>cw</turningDirection>
      <timeConstantUp>0.187</timeConstantUp>
      <timeConstantDown>0.1</timeConstantDown>
      <maxRotVelocity>2622</maxRotVelocity>
      <motorConstant>9.375e-7</motorConstant>
      <momentConstant>0.0086</momentConstant>
      <motorNumber>1</motorNumber>
      <rotorDragCoefficient>8e-5</rotorDragCoefficient>
      <rollingMomentCoefficient>1e-06</rollingMomentCoefficient>
      <rotorVelocitySlowdownSim>1</rotorVelocitySlowdownSim>
      <rotorVelocityUnits>rpm</rotorVelocityUnits>
      <escTransferFunction>
        <term1Coefficient>-14229.32</term1Coefficient>
        <term2Coefficient>39125.59</term2Coefficient>
        <term3Coefficient>86.67</term3Coefficient>
      </escTransferFunction>
      <joint_control_pid>
        <p>0.0001</p>
        <i>0</i>
        <d>0</d>
        <iMin>0</iMin>
        <iMax>0</iMax>
        <cmdMin>-0.1</cmdMin>
        <cmdMax>0.05</cmdMax>
      </joint_control_pid>
    </plugin>
    <plugin name='prop_3_motor_model' filename='libgazebo_motor_model.so'>
      <robotNamespace/>
      <jointName>prop_3_joint</jointName>
      <linkName>prop_3</linkName>
      <turningDirection>ccw</turningDirection>
      <timeConstantUp>0.187</timeConstantUp>
      <timeConstantDown>0.1</timeConstantDown>
      <maxRotVelocity>2622</maxRotVelocity>
      <motorConstant>9.375e-7</motorConstant>
      <momentConstant>0.0086</momentConstant>
      <motorNumber>2</motorNumber>
      <rotorDragCoefficient>8e-5</rotorDragCoefficient>
      <rollingMomentCoefficient>1e-06</rollingMomentCoefficient>
      <rotorVelocitySlowdownSim>1</rotorVelocitySlowdownSim>
      <rotorVelocityUnits>rpm</rotorVelocityUnits>
      <escTransferFunction>
        <term1Coefficient>-14229.32</term1Coefficient>
        <term2Coefficient>39125.59</term2Coefficient>
        <term3Coefficient>86.67</term3Coefficient>
      </escTransferFunction>
      <joint_control_pid>
        <p>0.0001</p>
        <i>0</i>
        <d>0</d>
        <iMin>0</iMin>
        <iMax>0</iMax>
        <cmdMin>-0.1</cmdMin>
        <cmdMax>0.05</cmdMax>
      </joint_control_pid>
    </plugin>
    <plugin name='prop_4_motor_model' filename='libgazebo_motor_model.so'>
      <robotNamespace/>
      <jointName>prop_4_joint</jointName>
      <linkName>prop_4</linkName>
      <turningDirection>cw</turningDirection>
      <timeConstantUp>0.187</timeConstantUp>
      <timeConstantDown>0.1</timeConstantDown>
      <maxRotVelocity>2622</maxRotVelocity>
      <motorConstant>9.375e-7</motorConstant>
      <momentConstant>0.0086</momentConstant>
      <motorNumber>3</motorNumber>
      <rotorDragCoefficient>8e-5</rotorDragCoefficient>
      <rollingMomentCoefficient>1e-06</rollingMomentCoefficient>
      <rotorVelocitySlowdownSim>1</rotorVelocitySlowdownSim>
      <rotorVelocityUnits>rpm</rotorVelocityUnits>
      <escTransferFunction>
        <term1Coefficient>-14229.32</term1Coefficient>
        <term2Coefficient>39125.59</term2Coefficient>
        <term3Coefficient>86.67</term3Coefficient>
      </escTransferFunction>
      <joint_control_pid>
        <p>0.0001</p>
        <i>0</i>
        <d>0</d>
        <iMin>0</iMin>
        <iMax>0</iMax>
        <cmdMin>-0.05</cmdMin>
        <cmdMax>0.1</cmdMax>
      </joint_control_pid>
    </plugin>
    <plugin name='prop_5_motor_model' filename='libgazebo_motor_model.so'>
      <robotNamespace/>
      <jointName>prop_5_joint</jointName>
      <linkName>prop_5</linkName>
      <turningDirection>ccw</turningDirection>
      <timeConstantUp>0.187</timeConstantUp>
      <timeConstantDown>0.1</timeConstantDown>
      <maxRotVelocity>2622</maxRotVelocity>
      <motorConstant>9.375e-7</motorConstant>
      <momentConstant>0.0086</momentConstant>
      <motorNumber>4</motorNumber>
      <rotorDragCoefficient>8e-5</rotorDragCoefficient>
      <rollingMomentCoefficient>1e-06</rollingMomentCoefficient>
      <rotorVelocitySlowdownSim>1</rotorVelocitySlowdownSim>
      <rotorVelocityUnits>rpm</rotorVelocityUnits>
      <escTransferFunction>
        <term1Coefficient>-14229.32</term1Coefficient>
        <term2Coefficient>39125.59</term2Coefficient>
        <term3Coefficient>86.67</term3Coefficient>
      </escTransferFunction>
      <joint_control_pid>
        <p>0.0001</p>
        <i>0</i>
        <d>0</d>
        <iMin>0</iMin>
        <iMax>0</iMax>
        <cmdMin>-0.1</cmdMin>
        <cmdMax>0.05</cmdMax>
      </joint_control_pid>
    </plugin>
    <plugin name='prop_6_motor_model' filename='libgazebo_motor_model.so'>
      <robotNamespace/>
      <jointName>prop_6_joint</jointName>
      <linkName>prop_6</linkName>
      <turningDirection>cw</turningDirection>
      <timeConstantUp>0.187</timeConstantUp>
      <timeConstantDown>0.1</timeConstantDown>
      <maxRotVelocity>2622</maxRotVelocity>
      <motorConstant>9.375e-7</motorConstant>
      <momentConstant>0.0086</momentConstant>
      <motorNumber>5</motorNumber>
      <rotorDragCoefficient>8e-5</rotorDragCoefficient>
      <rollingMomentCoefficient>1e-06</rollingMomentCoefficient>
      <rotorVelocitySlowdownSim>1</rotorVelocitySlowdownSim>
      <rotorVelocityUnits>rpm</rotorVelocityUnits>
      <escTransferFunction>
        <term1Coefficient>-14229.32</term1Coefficient>
        <term2Coefficient>39125.59</term2Coefficient>
        <term3Coefficient>86.67</term3Coefficient>
      </escTransferFunction>
      <joint_control_pid>
        <p>0.0001</p>
        <i>0</i>
        <d>0</d>
        <iMin>0</iMin>
        <iMax>0</iMax>
        <cmdMin>-0.05</cmdMin>
        <cmdMax>0.1</cmdMax>
      </joint_control_pid>
    </plugin>
    <plugin name='prop_7_motor_model' filename='libgazebo_motor_model.so'>
      <robotNamespace/>
      <jointName>prop_7_joint</jointName>
      <linkName>prop_7</linkName>
      <turningDirection>ccw</turningDirection>
      <timeConstantUp>0.187</timeConstantUp>
      <timeConstantDown>0.1</timeConstantDown>
      <maxRotVelocity>2622</maxRotVelocity>
      <motorConstant>9.375e-7</motorConstant>
      <momentConstant>0.0086</momentConstant>
      <motorNumber>6</motorNumber>
      <rotorDragCoefficient>8e-5</rotorDragCoefficient>
      <rollingMomentCoefficient>1e-06</rollingMomentCoefficient>
      <rotorVelocitySlowdownSim>1</rotorVelocitySlowdownSim>
      <rotorVelocityUnits>rpm</rotorVelocityUnits>
      <escTransferFunction>
        <term1Coefficient>-14229.32</term1Coefficient>
        <term2Coefficient>39125.59</term2Coefficient>
        <term3Coefficient>86.67</term3Coefficient>
      </escTransferFunction>
      <joint_control_pid>
        <p>0.0001</p>
        <i>0</i>
        <d>0</d>
        <iMin>0</iMin>
        <iMax>0</iMax>
        <cmdMin>-0.1</cmdMin>
        <cmdMax>0.05</cmdMax>
      </joint_control_pid>
    </plugin>
    <plugin name='prop_8_motor_model' filename='libgazebo_motor_model.so'>
      <robotNamespace/>
      <jointName>prop_8_joint</jointName>
      <linkName>prop_8</linkName>
      <turningDirection>cw</turningDirection>
      <timeConstantUp>0.187</timeConstantUp>
      <timeConstantDown>0.1</timeConstantDown>
      <maxRotVelocity>2622</maxRotVelocity>
      <motorConstant>9.375e-7</motorConstant>
      <momentConstant>0.0086</momentConstant>
      <motorNumber>7</motorNumber>
      <rotorDragCoefficient>8e-5</rotorDragCoefficient>
      <rollingMomentCoefficient>1e-06</rollingMomentCoefficient>
      <rotorVelocitySlowdownSim>1</rotorVelocitySlowdownSim>
      <rotorVelocityUnits>rpm</rotorVelocityUnits>
      <escTransferFunction>
        <term1Coefficient>-14229.32</term1Coefficient>
        <term2Coefficient>39125.59</term2Coefficient>
        <term3Coefficient>86.67</term3Coefficient>
      </escTransferFunction>
      <joint_control_pid>
        <p>0.0001</p>
        <i>0</i>
        <d>0</d>
        <iMin>0</iMin>
        <iMax>0</iMax>
        <cmdMin>-0.05</cmdMin>
        <cmdMax>0.1</cmdMax>
      </joint_control_pid>
    </plugin>
  </model>
</sdf>
